Traceback (most recent call last):
  File "/home/codespace/.cache/pypoetry/virtualenvs/jupyter-book-tutorial-X1HyCSxv-py3.10/lib/python3.10/site-packages/jupyter_cache/executors/utils.py", line 58, in single_nb_execution
    executenb(
  File "/home/codespace/.cache/pypoetry/virtualenvs/jupyter-book-tutorial-X1HyCSxv-py3.10/lib/python3.10/site-packages/nbclient/client.py", line 1305, in execute
    return NotebookClient(nb=nb, resources=resources, km=km, **kwargs).execute()
  File "/home/codespace/.cache/pypoetry/virtualenvs/jupyter-book-tutorial-X1HyCSxv-py3.10/lib/python3.10/site-packages/jupyter_core/utils/__init__.py", line 166, in wrapped
    return loop.run_until_complete(inner)
  File "/usr/local/python/3.10.13/lib/python3.10/asyncio/base_events.py", line 649, in run_until_complete
    return future.result()
  File "/home/codespace/.cache/pypoetry/virtualenvs/jupyter-book-tutorial-X1HyCSxv-py3.10/lib/python3.10/site-packages/nbclient/client.py", line 705, in async_execute
    await self.async_execute_cell(
  File "/home/codespace/.cache/pypoetry/virtualenvs/jupyter-book-tutorial-X1HyCSxv-py3.10/lib/python3.10/site-packages/nbclient/client.py", line 1058, in async_execute_cell
    await self._check_raise_for_error(cell, cell_index, exec_reply)
  File "/home/codespace/.cache/pypoetry/virtualenvs/jupyter-book-tutorial-X1HyCSxv-py3.10/lib/python3.10/site-packages/nbclient/client.py", line 914, in _check_raise_for_error
    raise CellExecutionError.from_cell_and_msg(cell, exec_reply_content)
nbclient.exceptions.CellExecutionError: An error occurred while executing the following cell:
------------------
import numpy as np
import IPython.display as display
from matplotlib import pyplot as plt
import io
import base64

ys = 200 + np.random.randn(100)
x = [x for x in range(len(ys))]

fig = plt.figure(figsize=(4, 3), facecolor='w')
plt.plot(x, ys, '-')
plt.fill_between(x, ys, 195, where=(ys > 195), facecolor='g', alpha=0.6)
plt.title("Sample Visualization", fontsize=10)

data = io.BytesIO()
plt.savefig(data)
image = F"data:image/png;base64,{base64.b64encode(data.getvalue()).decode()}"
alt = "Sample Visualization"
display.display(display.Markdown(F"""![{alt}]({image})"""))
plt.close(fig)
------------------


[0;31m---------------------------------------------------------------------------[0m
[0;31mModuleNotFoundError[0m                       Traceback (most recent call last)
Cell [0;32mIn[3], line 3[0m
[1;32m      1[0m [38;5;28;01mimport[39;00m [38;5;21;01mnumpy[39;00m [38;5;28;01mas[39;00m [38;5;21;01mnp[39;00m
[1;32m      2[0m [38;5;28;01mimport[39;00m [38;5;21;01mIPython[39;00m[38;5;21;01m.[39;00m[38;5;21;01mdisplay[39;00m [38;5;28;01mas[39;00m [38;5;21;01mdisplay[39;00m
[0;32m----> 3[0m [38;5;28;01mfrom[39;00m [38;5;21;01mmatplotlib[39;00m [38;5;28;01mimport[39;00m pyplot [38;5;28;01mas[39;00m plt
[1;32m      4[0m [38;5;28;01mimport[39;00m [38;5;21;01mio[39;00m
[1;32m      5[0m [38;5;28;01mimport[39;00m [38;5;21;01mbase64[39;00m

[0;31mModuleNotFoundError[0m: No module named 'matplotlib'

